Workbook

Sheet Sumurry of ccg value
A2: Products | B2: Value
A3: Glassware | B3: ='Glassware '!G19 -> 410324
A4: Baroque
A5: Mono Atrevo | B5: ='Mono Portions Artevo '!#REF! -> #REF!
A6: Platters & bowls | B6: ='Platters & Bowls'!L12 -> 7200
A7: Metal ware | B7: ='Mettal ware for Buffet '!J26 -> 81000
A8: Mirror ware | B8: ='mirrorware for buffets '!K21 -> 37600
A9: plates | B9: ='Plates '!J6 -> 16800
A10: Cutlury | B10: ='Cutlury '!#REF! -> #REF!
A11: Total | B11: =SUM(B3:B10) -> #REF!

Sheet Mono Portions Artevo 
A2: Sr # | B2: Description | C2: Product Code | D2: Dimensions in cm | E2: Quantity | F2: Our Purchase Value | G2: Total Purchase value | H2: ROI on Rent | I2: Breakage per unit | J2: Rental per unit | K2: Client brakage
A3: 1 | B3: Small Rectangular Plate ( Half ) | C3: SRAM 4 | D3: L- 11 x B - 7.5 | E3: 36 | F3: 182 | G3: =E3*F3 -> 6552 | H3: =J3/F3 -> 0.13736264 | I3: 250 | J3: =I3*10% -> 25 | K3: =I3*E3 -> 9000
A4: 2 | B4: Rectangular Platter | C4: SRAM 6 | D4: L-33 x B-11.25 | E4: 24 | F4: 536 | G4: =E4*F4 -> 12864 | H4: =J4/F4 -> 0.13992537 | I4: 750 | J4: =I4*10% -> 75 | K4: =I4*E4 -> 18000
A5: 4 | B5: Small Round Edge Katori ( 150 ml ) | C5: SRAM 10 | D5: D-8.5 x H-4 | E5: 100 | F5: 124 | G5: =E5*F5 -> 12400 | H5: =J5/F5 -> 0.2016129 | I5: 200 | J5: 25 | K5: =I5*E5 -> 20000
A6: 5 | B6: Without handle Bowl | C6: SRAM 12 | D6: 50 ml H - 1.75'' x W 2.5'' | E6: 60 | F6: 80 | G6: =E6*F6 -> 4800 | H6: =J6/F6 -> 0.3125 | I6: 60 | J6: 25 | K6: =I6*E6 -> 3600
A7: 6 | B7: Oval Dish | C7: SRAM 13 | D7: L-14 x B-7.0 x H-3 | E7: =40+30+110-50 -> 130 | F7: 148 | G7: =E7*F7 -> 19240 | H7: =J7/F7 -> 0.16891892 | I7: 200 | J7: 25 | K7: =I7*E7 -> 26000
A8: 8 | B8: Small Round Ramekin | C8: SRAM 18 | D8: D-8 x H-2.5 | E8: 176 | F8: 67 | G8: =E8*F8 -> 11792 | H8: =J8/F8 -> 0.29850746 | I8: 100 | J8: 20 | K8: =I8*E8 -> 17600
A9: 9 | B9: Sauce Dip Bowl ( 75 ml ) | C9: SRAM 19 | D9: D-7.5 x H-2.5 | E9: =266+54+18-180 -> 158 | F9: 59 | G9: =E9*F9 -> 9322 | H9: =J9/F9 -> 0.33898305 | I9: 100 | J9: 20 | K9: =I9*E9 -> 15800
A10: 10 | B10: Square Katori | C10: SRAM 20 | D10: L-5.5 x B-5.5 x H- 3 | E10: =50+100+94+27+9+40 -> 320 | F10: 59 | G10: =E10*F10 -> 18880 | H10: =J10/F10 -> 0.33898305 | I10: 100 | J10: 20 | K10: =I10*E10 -> 32000
A11: 11 | B11: Uneven Quarter plate Indigo Blue | C11: SRAM 21 | D11: 16 CM | E11: 33 | F11: 195 | G11: =E11*F11 -> 6435 | H11: =J11/F11 -> 0.17948718 | I11: 250 | J11: 35 | K11: =I11*E11 -> 8250
A12: 12 | B12: Leaf Mono Portion Mix Color | C12: SRAM 23 | E12: 20 | F12: 132 | G12: =E12*F12 -> 2640 | H12: =J12/F12 -> 0.22727273 | I12: 200 | J12: 30 | K12: =I12*E12 -> 4000
A13: 13 | B13: Uneven Quarter plate Earth | C13: SRAM 22 | D13: 16 CM | E13: 59 | F13: 195 | G13: =E13*F13 -> 11505 | H13: =J13/F13 -> 0.17948718 | I13: 250 | J13: 35 | K13: =I13*E13 -> 14750
A14: 14 | B14: Mini Bowl Mix Colour | C14: SR-MB 1 | E14: 80 | F14: 74 | G14: =E14*F14 -> 5920 | H14: =J14/F14 -> 0.27027027 | I14: 100 | J14: 20 | K14: =I14*E14 -> 8000
G15: =SUM(G3:G14) -> 122350 | H15: =(H3+H4+H5+H6+H7+H8+H9+H10+H11+H12+H13+H14)/12 -> 0.2327759 | K15: =SUM(K3:K14) -> 177000

Sheet Glassware 
A2: Discription | B2: Sr.No | C2: Code No | D2: Measurement | E2: Quantity | F2: Our Purchase | G2: P.VALUE | H2: ROI on Rent | I2: Rent | J2: Breakage | K2: Value
A3: White W | B3: 1 | C3: SRG 1 | D3: Wine 02 40,5cl 13 ¾oz H 215mm 8 ½" D 86mm 3 ½" | E3: 164 | F3: 287 | G3: =E3*F3 -> 47068 | H3: =I3/F3 -> 0.13937282 | I3: 40 | J3: 380 | K3: =E3*J3 -> 62320
A4: Red W | B4: 2 | C4: SRG 2 | D4: Wine 01 52cl 17 ¾oz H 230mm 9" D 93mm 3 ¾" | E4: 142 | F4: 294 | G4: =E4*F4 -> 41748 | H4: =I4/F4 -> 0.13605442 | I4: 40 | J4: 380 | K4: =E4*J4 -> 53960
A5: Champagne | B5: 3 | C5: SRG 3 | D5: Champagne flute 09 22cl 7 ½oz H 250mm 10" D 70mm 2 ¾" | E5: 128 | F5: 286 | G5: =E5*F5 -> 36608 | H5: =I5/F5 -> 0.13986014 | I5: 40 | J5: 380 | K5: =E5*J5 -> 48640
A6: Champagne Saucer | B6: 4 | C6: SRG 4 | D6: Paris Saucer Champ. 28 26 cl 8 ¾oz H 131mm 5 ¼" D 96mm 3 ¾" | E6: 25 | F6: 245 | G6: =E6*F6 -> 6125 | H6: =I6/F6 -> 0.081632653 | I6: 20 | J6: 350 | K6: =E6*J6 -> 8750
A7: cocktail | B7: 5 | C7: SRG 5 | D7: Martini / Saucer Champ. 08 25 cl 8 ½oz H 144mm 5 ¾" D 98mm 4 " | E7: 25 | F7: 407 | G7: =E7*F7 -> 10175 | H7: =I7/F7 -> 0.098280098 | I7: 40 | J7: 550 | K7: =E7*J7 -> 13750
A8: martini | B8: 6 | C8: SRG 6 | D8: Martini 28 30 cl 10 ¼oz H 188mm 7 ½" D 125mm 4 ½" | E8: 49 | F8: 306 | G8: =E8*F8 -> 14994 | H8: =I8/F8 -> 0.065359477 | I8: 20 | J8: 400 | K8: =E8*J8 -> 19600
A9: Gin & Tonic/ cocktail | B9: 7 | C9: SRG 7 | D9: Gin Tonic 00 63 cl 21 ½oz H 203mm 8 " D 105mm 4 ¼" | E9: 92 | F9: 256 | G9: =E9*F9 -> 23552 | H9: =I9/F9 -> 0.15625 | I9: 40 | J9: 400 | K9: =E9*J9 -> 36800
A10: Baloon | B10: 8 | C10: SRG 8 | D10: Brandy 18 40 cl 13 ½ oz H 138mm 5 ½" D 95mm 3 ¾" | E10: 13 | F10: 282 | G10: =E10*F10 -> 3666 | H10: =I10/F10 -> 0.14184397 | I10: 40 | J10: 350 | K10: =E10*J10 -> 4550
A11: Whiskey tasting glass | B11: 9 | C11: SRG 9 | D11: Single Malt Whiskey 32 20 cl ¾oz | E11: 48 | F11: 282 | G11: =E11*F11 -> 13536 | H11: =I11/F11 -> 0.070921986 | I11: 20 | J11: 400 | K11: =E11*J11 -> 19200
A12: cocktail Tumbler | B12: 10 | C12: SRG 10 | D12: Cocktail tumbler 15 25 cl 8 ½oz H 90mm 3 ½" D 79mm 3 ¼" | E12: 254 | F12: 164 | G12: =E12*F12 -> 41656 | H12: =I12/F12 -> 0.12195122 | I12: 20 | J12: 250 | K12: =E12*J12 -> 63500
A13: old fashiond | B13: 11 | C13: SRG 11 | D13: Singapore Double Old Fashioned 11oz (31cl) | E13: =169+24 -> 193 | F13: 144 | G13: =E13*F13 -> 27792 | H13: =I13/F13 -> 0.27777778 | I13: 40 | J13: 300 | K13: =E13*J13 -> 57900
A14: old fashiond | B14: 12 | C14: SRG 12 | D14: Old Fashioned 16 39 cl 13 oz H 90mm 3 ½" D 95mm 3 ¾" | E14: 216 | F14: 158 | G14: =E14*F14 -> 34128 | H14: =I14/F14 -> 0.22151899 | I14: 35 | J14: 300 | K14: =E14*J14 -> 64800
A15: High ball | B15: 13 | C15: SRG 13 | D15: Singapore Hiball 11.25oz (32cl) | E15: =185+18 -> 203 | F15: 176 | G15: =E15*F15 -> 35728 | H15: =I15/F15 -> 0.22727273 | I15: 40 | J15: 300 | K15: =E15*J15 -> 60900
A16: High ball | B16: 14 | C16: SRG 14 | D16: Highball 12 46 cl 15 ½oz H 145mm 5 ¾" D 76mm 3 " | E16: 216 | F16: 182 | G16: =E16*F16 -> 39312 | H16: =I16/F16 -> 0.19230769 | I16: 35 | J16: 300 | K16: =E16*J16 -> 64800
A17: Beer | B17: 15 | C17: SRG 15 | D17: Pilsener 19 36 cl 13 oz H 184mm 7 ¼" D 79mm 3 ¼" | E17: 61 | F17: 276 | G17: =E17*F17 -> 16836 | H17: =I17/F17 -> 0.14492754 | I17: 40 | J17: 370 | K17: =E17*J17 -> 22570
A18: Beer | B18: 16 | C18: SRG 16 | D18: Beer tumbler 19 38 cl 12 ¾oz H 212mm 8 ¼" D 80mm 3 ¼" | E18: 60 | F18: 290 | G18: =E18*F18 -> 17400 | H18: =I18/F18 -> 0.13793103 | I18: 40 | J18: 370 | K18: =E18*J18 -> 22200
G19: =SUM(G3:G18) -> 410324 | H19: =(H3+H4+H5+H6+H7+H8+H9+H10+H11+H12+H13+H14+H15+H16+H17+H18)/16 -> 0.14707891 | K19: =SUM(K3:K18) -> 624240

Sheet Baroque 
A1: SR. NO | B1: Code | C1: Description | D1: Specifications | E1: Quantity | F1: Our Purchase | G1: Total Purchase value | H1: ROI on Rent | I1: Rent | J1: Breakage | K1: Value
A2: 1 | B2: SRB 1 | C2: Ø 25 cm - h 6,5 cm I Ø 9,8 inch - h 2,6 inch | D2: Baroque dripping gold Glass Bowl | E2: 8 | F2: 968 | G2: =E2*F2 -> 7744 | H2: =I2/F2 -> 0.20661157 | I2: 200 | J2: 1200 | K2: =E2*J2 -> 9600
A3: 2 | B3: SRB 2 | C3: Ø 34 cm - h 10,5 cm I Ø 13,4 inch - h 4,1 inch | D3: Baroque dripping glold Glass Plate with Stand | E3: 8 | F3: 1800 | G3: =E3*F3 -> 14400 | H3: =I3/F3 -> 0.19444444 | I3: 350 | J3: 2200 | K3: =E3*J3 -> 17600
A4: 3 | B4: SRB 3 | C4: Ø 37 cm - h 1,8 cm I Ø 14,6 inch - h 0,7 inch | D4: Baroque dripping glod Glass platter round | E4: 12 | F4: 2060 | G4: =E4*F4 -> 24720 | H4: =I4/F4 -> 0.16990291 | I4: 350 | J4: 2500 | K4: =E4*J4 -> 30000
D5: Baroque dripping gold dinner Glass Plate | E5: 12
A6: 4 | B6: SRB 4 | C6: Ø 22 cm - h 2,5 cm I Ø 8,7 inch - h 1 inch | D6: Baroque dripping gold dessert Glass Plate | E6: 12 | F6: 750 | G6: =E6*F6 -> 9000 | H6: =I6/F6 -> 0.26666667 | I6: 200 | J6: 1000 | K6: =E6*J6 -> 12000
D7: Baroque dripping gold Quater Glass Plate | E7: 12
A8: 5 | B8: SRB 5 | C8: Ø 37 cm - h 1,7 cm I Ø 14,6 inch - h 0,7 inch | D8: Baroque print Glass Plate | E8: 8 | F8: 2113 | G8: =E8*F8 -> 16904 | H8: =I8/F8 -> 0.16564127 | I8: 350 | J8: 2500 | K8: =E8*J8 -> 20000
A9: 6 | B9: SRB 6 | C9: Ø 26 cm - h 10,5 cm Ø 10,2 inch - h 4,1 inch | D9: Baroque print Glass Plate with Stand small | E9: 6 | F9: 1098 | G9: =E9*F9 -> 6588 | H9: =I9/F9 -> 0.27322404 | I9: 300 | J9: 1500 | K9: =E9*J9 -> 9000
A10: 7 | B10: SRB 7 | C10: Ø 22 cm - h 3 cm I Ø 8,7 inch - h 1,2 inch | D10: uneven Baroque gold Glass Plate | E10: 32 | F10: 744 | G10: =E10*F10 -> 23808 | H10: =I10/F10 -> 0.2688172 | I10: 200 | J10: 1000 | K10: =E10*J10 -> 32000
A11: 8 | B11: SRB 8 | C11: Ø 28 cm - h 8,5 cm | D11: Baroque gold buffet Glass Bowl | E11: 8 | F11: 968 | G11: =E11*F11 -> 7744 | H11: =I11/F11 -> 0.20661157 | I11: 200 | J11: 1200 | K11: =E11*J11 -> 9600
A12: 9 | B12: SRB 9 | C12: Ø 25 cm - h 14 cm Ø 9,8 inch - h 5,5 inch | D12: Baroque printed gold Glass Bowl with Stand | E12: 6 | F12: 1989 | G12: =E12*F12 -> 11934 | H12: =I12/F12 -> 0.17596782 | I12: 350 | J12: 2500 | K12: =E12*J12 -> 15000
A13: 10 | B13: SRB 10 | C13: 10 cm * 10 cm | D13: Baroque square Mono Portions | E13: 240 | F13: 136 | G13: =E13*F13 -> 32640 | H13: =I13/F13 -> 0.25735294 | I13: 35 | J13: 250 | K13: =E13*J13 -> 60000
A14: 11 | B14: SRB 11 | C14: 10 cm * 10 cm | D14: Baroque round Mono Portions | E14: 240 | F14: 142 | G14: =E14*F14 -> 34080 | H14: =I14/F14 -> 0.24647887 | I14: 35 | J14: 250 | K14: =E14*J14 -> 60000
A15: 12 | B15: SRB 12 | C15: 8.25 cm * 11.5 cm | D15: baroque oval Mono Portions | E15: 240 | F15: 148 | G15: =E15*F15 -> 35520 | H15: =I15/F15 -> 0.23648649 | I15: 35 | J15: 250 | K15: =E15*J15 -> 60000
A16: 13 | B16: SRB 13 | C16: 7.5 cm * 10 cm | D16: Baroque oval small Mono Portions | E16: 240 | F16: 142 | G16: =E16*F16 -> 34080 | H16: =I16/F16 -> 0.24647887 | I16: 35 | J16: 250 | K16: =E16*J16 -> 60000
A17: 14 | B17: SRB RG 1 | C17: 10 cm * 10 cm | D17: Baroque round Rose gold Mono Portions | E17: 59 | F17: 200 | G17: =E17*F17 -> 11800 | H17: =I17/F17 -> 0.2 | I17: 40 | J17: 275 | K17: =E17*J17 -> 16225
A18: 15 | B18: SRB RGP 1 | C18: 32 Cm * 18cm | D18: Baroque round Rose gold long plate | E18: 18 | F18: 1100 | G18: =E18*F18 -> 19800 | H18: =I18/F18 -> 0.22727273 | I18: 250 | J18: 1500 | K18: =E18*J18 -> 27000
A19: 16 | B19: SRB 14 | C19: Dimensions: Ext: 59,3x23,5cm, Height: 27,6cm | D19: Metal and Glass leaf pate | E19: 4 | F19: 4336 | G19: =E19*F19 -> 17344 | H19: =I19/F19 -> 0.13837638 | I19: 600 | J19: 5500 | K19: =E19*J19 -> 22000
... A24: 21 | B24: SRB 19 | C24: Dimensions: Ext: 35,0x13,0cm, Height: 31,5cm, Capacity: 195 ml | D24: Metal Gold Stand with 3 glass plates | E24: 4 | F24: 5310 | G24: =E24*F24 -> 21240 | H24: =I24/F24 -> 0.12241055 | I24: 650 | J24: 6500 | K24: =E24*J24 -> 26000
A25: 22 | D25: Glass Mono portion | E25: 4 | F25: 400 | G25: =E25*F25 -> 1600 | H25: =I25/F25 -> 0.25 | I25: 100 | J25: 600 | K25: =E25*J25 -> 2400
A26: 23 | D26: gold round stairway charlie | E26: 4 | F26: 4500 | G26: =E26*F26 -> 18000 | H26: =I26/F26 -> 0.16666667 | I26: 750 | J26: 7500 | K26: =E26*J26 -> 30000
A27: 24 | D27: Rose gold bowl (Large) | E27: 8 | F27: 793 | G27: =E27*F27 -> 6344 | H27: =I27/F27 -> 0.37831021 | I27: 300 | J27: 2000 | K27: =E27*J27 -> 16000
A28: 25 | D28: Rose gold bowl (Mid size) | E28: 8 | F28: 515 | G28: =E28*F28 -> 4120 | H28: =I28/F28 -> 0.38834951 | I28: 200 | J28: 1800 | K28: =E28*J28 -> 14400
A29: 26 | D29: Rose gold bowl (Small size) | E29: 32 | F29: 300 | G29: =E29*F29 -> 9600 | H29: =I29/F29 -> 0.33333333 | I29: 100 | J29: 600 | K29: =E29*J29 -> 19200
A30: 27 | D30: Metal Gold Stand with 17 glass plates | E30: 6 | F30: 12500 | G30: =E30*F30 -> 75000 | H30: =I30/F30 -> 0.16 | I30: 2000 | J30: 15000 | K30: =E30*J30 -> 90000
A31: 28 | B31: SRB 20 | C31: Dimensions: Ext: 78,0x70,0cm, Height: 15,0cm (FULL SET) | D31: Metal Stand and glass platter (Fell set ) 3 units | E31: 4 | F31: 12980 | G31: =E31*F31 -> 51920 | H31: =I31/F31 -> 0.1155624 | I31: 1500 | J31: 15600 | K31: =E31*J31 -> 62400
A32: 29 | B32: SRB 32 | D32: Baroque gold design Glass platter round | E32: 3 | F32: 472 | G32: =E32*F32 -> 1416 | H32: =I32/F32 -> 0.74152542 | I32: 350 | J32: 3000 | K32: =E32*J32 -> 9000
A33: 30 | B33: SRB 33 | D33: Baroque gold & white Glass platter round | E33: 3 | F33: 472 | G33: =E33*F33 -> 1416 | H33: =I33/F33 -> 0.74152542 | I33: 350 | J33: 3000 | K33: =E33*J33 -> 9000
A34: 31 | B34: SRB 34 | D34: Baroque gold & white design Glass platter round ( LARGE ) | E34: 3 | F34: 472 | G34: =E34*F34 -> 1416 | H34: =I34/F34 -> 0.52966102 | I34: 250 | J34: 2500 | K34: =E34*J34 -> 7500
A35: 32 | B35: SRB 35 | D35: Baroque gold & white design Glass platter round ( MID ) | E35: 3 | F35: 400 | G35: =E35*F35 -> 1200 | H35: =I35/F35 -> 0.5 | I35: 200 | J35: 2000 | K35: =E35*J35 -> 6000
A36: 33 | B36: SRB 36 | D36: Baroque Gold Mono Portions With Stand | E36: 150 | F36: 265 | G36: =E36*F36 -> 39750 | H36: =I36/F36 -> 0.18867925 | I36: 50 | J36: 400 | K36: =E36*J36 -> 60000
A37: 34 | B37: SRB 37 | D37: Baroque Black Mono Portions With Stand | E37: =150-18 -> 132 | F37: 278 | G37: =E37*F37 -> 36696 | H37: =I37/F37 -> 0.17985612 | I37: 50 | J37: 400 | K37: =E37*J37 -> 52800
A38: 35 | B38: SRB 38 | D38: White and gold bread plate | E38: 33 | F38: 500 | G38: =E38*F38 -> 16500 | H38: =I38/F38 -> 0.2 | I38: 100 | J38: 600 | K38: =E38*J38 -> 19800
A39: 36 | B39: SRB 28 | D39: White & Gold bread / dessert Box Large | E39: 6 | F39: 2330 | G39: =E39*F39 -> 13980 | H39: =I39/F39 -> 0.17167382 | I39: 400 | J39: 3500 | K39: =E39*J39 -> 21000
A40: 37 | B40: SRB 29 | D40: White & Gold bread / dessert Box Big | E40: 4 | I40: 350 | J40: 2500 | K40: =E40*J40 -> 10000
A41: 38 | B41: SRB 32 | D41: White & Gold bread / dessert Box MiD | E41: 8 | I41: 300 | J41: 2000 | K41: =E41*J41 -> 16000
A42: 39 | B42: SRB 33 | D42: White & Gold bread / dessert Box Small | E42: 8 | I42: 250 | J42: 1500 | K42: =E42*J42 -> 12000
A43: 40 | B43: SRB 20 | C43: 1 UNIT Large | D43: Metal Stand and glass platter L | E43: 4 | F43: =12980*50% -> 6490 | G43: =E43*F43 -> 25960 | H43: =I43/F43 -> 0.10785824 | I43: 700 | J43: 7800 | K43: =E43*J43 -> 31200
A44: 41 | B44: SRB 20 | C44: 1 UINTS Mid | D44: Metal Stand and glass platter M | E44: 4 | F44: =12980*30% -> 3894 | G44: =E44*F44 -> 15576 | H44: =I44/F44 -> 0.1540832 | I44: 600 | J44: 6500 | K44: =E44*J44 -> 26000
...

Sheet Platters & Bowls
A2: Sr No | B2: Code | C2: Description | D2: Green | E2: Grey | F2: Pink | G2: Our Purchase | H2: P.VALUE | I2: ROI on Rent | J2: Rent | K2: Breakage | L2: Value
A3: 1 | B3: SRAB 1 | C3: Tall Edge Big Bowl D-24 x H-9.5 | D3: 3 | E3: 1 | F3: 6 | G3: 1095 | H3: =G3*F3+E3+D3 -> 6574 | I3: =J3/G3 -> 0.1369863 | J3: =K3*10% -> 150 | K3: 1500 | L3: =(D3+E3+F3)*K3 -> 15000
A4: 2 | B4: SRAB 2 | C4: Tall Edge Small Bowl D-14 x H-8 | D4: 8 | E4: 8 | F4: 8 | G4: 404 | H4: =G4*F4+E4+D4 -> 3248 | I4: =J4/G4 -> 0.24752475 | J4: 100 | K4: 750 | L4: =(D4+E4+F4)*K4 -> 18000
A5: 3 | B5: SRAB 3 | C5: Double Portion Serving Bowl D-25 x H-6.5 | D5: 12 | E5: 8 | F5: 8 | G5: 905 | H5: =G5*F5+E5+D5 -> 7260 | I5: =J5/G5 -> 0.13259669 | J5: 120 | K5: 1250 | L5: =(D5+E5+F5)*K5 -> 35000
A6: 4 | B6: SRAB 4 | C6: Single Portion Serving Bowl D-20 x H-6.5 | D6: 8 | E6: 8 | F6: 8 | G6: 536 | H6: =G6*F6+E6+D6 -> 4304 | I6: =J6/G6 -> 0.18656716 | J6: 100 | K6: 750 | L6: =(D6+E6+F6)*K6 -> 18000
A7: 5 | B7: SRAB 5 | C7: Sink Bowl ( 650 ml ) D-15 x H-8 | D7: 8 | E7: 8 | F7: 8 | G7: 338 | H7: =G7*F7+E7+D7 -> 2720 | I7: =J7/G7 -> 0.29585799 | J7: 100 | K7: 500 | L7: =(D7+E7+F7)*K7 -> 12000
A8: 6 | B8: SRAM 7 | C8: Atle / Krish Bowl Small ( 325 ml D-13 x H- 6.5 | D8: 35 | G8: 350 | H8: =G8*D8 -> 12250 | I8: =J8/G8 -> 0.14285714 | J8: 50 | K8: 350 | L8: =(D8+E8+F8)*K8 -> 12250
A9: 7 | B9: SRP 1 | C9: Rectangle One 37.0cm x 16.5cm (14½" x 6½") - Steelite | D9: 12 | E9: 0 | F9: 0 | G9: 3614 | H9: =D9*G9 -> 43368 | I9: =J9/G9 -> 0.0968456 | J9: 350 | K9: 4000 | L9: =D9*K9 -> 48000
A10: 8 | B10: SRP 2 | C10: Vesuvius Amber Square One 27cm x 27cm (10 5/8\ x 10 5/8\) -Steelite | D10: 12 | E10: 0 | F10: 0 | G10: 4090 | H10: =D10*G10 -> 49080 | I10: =J10/G10 -> 0.085574572 | J10: 350 | K10: 4500 | L10: =D10*K10 -> 54000
A11: 9 | B11: SRP 3 | C11: Ink Nomad Blue Plate Coupe 25.5cm 10\ - Steelite | D11: 12 | E11: 0 | F11: 0 | G11: 1052 | H11: =D11*G11 -> 12624 | I11: =J11/G11 -> 0.33269962 | J11: 350 | K11: 1500 | L11: =D11*K11 -> 18000
A12: 10 | B12: SRAB 9 | C12: Rectangle One 37.0cm x 16.5cm (14½" x 6½") - Indigo blue | D12: 8 | E12: 0 | F12: 0 | G12: 663 | H12: =D12*G12 -> 5304 | I12: =J12/G12 -> 0.37707391 | J12: 250 | K12: 900 | L12: =D12*K12 -> 7200
A13: 11 | B13: SRGB -21 | C13: Black glass bowl - 400 ml | D13: 32 | G13: 354 | H13: =D13*G13 -> 11328 | I13: =J13/G13 -> 0.16949153 | J13: 60 | K13: 500 | L13: =D13*K13 -> 16000
A14: 12 | B14: SRGB -20 | C14: Brown glass bowl - 400 ml | D14: 32 | G14: 354 | H14: =D14*G14 -> 11328 | I14: =J14/G14 -> 0.16949153 | J14: 60 | K14: 500 | L14: =D14*K14 -> 16000
A15: 13 | B15: SRAM -30 | C15: Rectangular Glass platter ( green 11 , blue 11 , red 11) | D15: 33 | G15: 443 | H15: =D15*G15 -> 14619 | I15: =J15/G15 -> 0.45146727 | J15: 200 | K15: 700 | L15: =D15*K15 -> 23100
A16: 14 | B16: SRAM 6 | C16: Rectangular Platter ( Yellow with white inside ) | D16: 24 | G16: 550 | H16: =D16*G16 -> 13200 | I16: =J16/G16 -> 0.36363636 | J16: 200 | K16: 800 | L16: =D16*K16 -> 19200
A17: 15 | B17: SRGB-22 | C17: Glass Bowl White | D17: 210 | G17: 54 | H17: =D17*G17 -> 11340 | I17: =J17/G17 -> 0.46296296 | J17: 25 | K17: 100 | L17: =D17*K17 -> 21000
A18: 16 | B18: SRAG -20 | C18: Glass Platter long in black 22 inch by 6 inch | D18: 8 | G18: =750+135 -> 885 | H18: =D18*G18 -> 7080 | I18: =J18/G18 -> 0.79096045 | J18: 700 | K18: 3500 | L18: =D18*K18 -> 28000
A19: 17 | B19: SRAB 10 | C19: Rectangle One 37.0cm x 16.5cm (14½" x 6½") - Olive green | D19: 10 | E19: 0 | F19: 0 | G19: 663 | H19: =D19*G19 -> 6630 | I19: =J19/G19 -> 0.37707391 | J19: 250 | K19: 900 | L19: =D19*K19 -> 9000
G20: =SUM(G3:G19) -> 16350 | I20: =(I3+I4+I5+I6+I7+I8+I9+I10+I11+I12+I19)/11 -> 0.2192416 | K20: =SUM(K3:K19) -> 23000 | L20: =SUM(L3:L19) -> 369750

Sheet Mettal ware for Buffet 
A2: Sl No | B2: DESCRIPTION | C2: ITEM CODE | D2: Quantity | E2: Our Purchase | F2: P.VALUE | G2: ROI on Rent | H2: Rent | I2: Breakage | J2: Value
A3: 1 | B3: Metal Risers 1 Black Matte FInish 25 x 21 x 15cm | C3: SR MBW 1 | D3: 7 | E3: 845 | F3: =D3*E3 -> 5915 | G3: =H3/E3 -> 0.35502959 | H3: 300 | I3: 1200 | J3: =D3*I3 -> 8400
A4: 2 | B4: Metal Risers 1 Black Matte FInish 25 x 21 x 20cm | C4: SR MBW 2 | D4: 6 | E4: 845 | F4: =D4*E4 -> 5070 | G4: =H4/E4 -> 0.35502959 | H4: 300 | I4: 1200 | J4: =D4*I4 -> 7200
A5: 3 | B5: Metal Risers 1 Black Matte FInish 25 x 21 x 25cm | C5: SR MBW 3 | D5: 4 | E5: 1428 | F5: =D5*E5 -> 5712 | G5: =H5/E5 -> 0.35014006 | H5: 500 | I5: 2000 | J5: =D5*I5 -> 8000
A6: 4 | B6: Metal Risers 6 Black Matte FInish D21cm x H10cm | C6: SR MBW 4 | D6: 6 | E6: 860 | F6: =D6*E6 -> 5160 | G6: =H6/E6 -> 0.34883721 | H6: 300 | I6: 1200 | J6: =D6*I6 -> 7200
A7: 5 | B7: Metal Risers 6 Black Matte FInish D21cm x H20cm | C7: SR MBW 5 | D7: 6 | E7: 1310 | F7: =D7*E7 -> 7860 | G7: =H7/E7 -> 0.38167939 | H7: 500 | I7: 2000 | J7: =D7*I7 -> 12000
A8: 6 | B8: Metal Risers 2 Black Matte FInish 18 x 18 x 10 cm | C8: SR MBW 6 | D8: 6 | E8: 609 | F8: =D8*E8 -> 3654 | G8: =H8/E8 -> 0.41050903 | H8: 250 | I8: 1000 | J8: =D8*I8 -> 6000
A9: 7 | B9: Metal Risers 2 Black Matte FInish 18 x 18 x 15 cm | C9: SR MBW 7 | D9: 6 | E9: 713 | F9: =D9*E9 -> 4278 | G9: =H9/E9 -> 0.35063114 | H9: 250 | I9: 1000 | J9: =D9*I9 -> 6000
A10: 8 | B10: Metal Risers 2 Black Matte FInish 18 x 18 x 20 cm | C10: SR MBW 8 | D10: 6 | E10: 871 | F10: =D10*E10 -> 5226 | G10: =H10/E10 -> 0.34443169 | H10: 300 | I10: 1200 | J10: =D10*I10 -> 7200
A11: 9 | B11: Metal Risers 1 Black Matte FInish 25 x 21 x 10cm | C11: SR MBW 9 | D11: 6 | E11: 520 | F11: =D11*E11 -> 3120 | G11: =H11/E11 -> 0.48076923 | H11: 250 | I11: 1000 | J11: =D11*I11 -> 6000
A12: 10 | B12: Metal Risers 1 Black Matte FInish 25 x 21 x 15cm | C12: SR MBW 10 | D12: 5 | E12: 606 | F12: =D12*E12 -> 3030 | G12: =H12/E12 -> 0.41254125 | H12: 250 | I12: 1000 | J12: =D12*I12 -> 5000
A13: 11 | B13: Metal Risers 1 Black Matte FInish 25 x 21 x 20cm | C13: SR MBW 11 | D13: 6 | E13: 705 | F13: =D13*E13 -> 4230 | G13: =H13/E13 -> 0.35460993 | H13: 250 | I13: 1000 | J13: =D13*I13 -> 6000
A14: 12 | B14: Half Round Solid Riser Big PVD Champagne Gold Matte (1 set has 2 units) | C14: SR MBW-12 | D14: 1 | E14: 1191 | F14: =D14*E14 -> 1191 | G14: =H14/E14 -> 0.33585223 | H14: 400 | I14: 2000 | J14: =D14*I14 -> 2000
... A19: 17 | B19: Uneven Gold cake / buffet riser | C19: SR BMW -15 | D19: 3 | E19: 891 | F19: =D19*E19 -> 2673 | G19: =H19/E19 -> 0.11223345 | H19: 100 | I19: 800 | J19: =D19*I19 -> 2400
A20: 18 | B20: Metal Risers Gold ( ROUND MID SIZE ) | C20: SR GOLD -1 | D20: 6 | E20: 1234 | F20: =E20*D20 -> 7404 | G20: =H20/E20 -> 0.28363047 | H20: 350 | I20: 1500 | J20: =D20*I20 -> 9000
A21: 19 | B21: Half Round Solid Riser Gold (1 set has 2 units) - Large | C21: SR GOLD -2 | D21: 6 | E21: 1083 | F21: =E21*D21 -> 6498 | G21: =H21/E21 -> 0.46168052 | H21: 500 | I21: =2500 -> 2500 | J21: =D21*I21 -> 15000
A22: 20 | B22: Half Round Solid Riser Gold (1 set has 2 units) - Samll | C22: SR GOLD -3 | D22: 6 | E22: 813 | F22: =E22*D22 -> 4878 | G22: =H22/E22 -> 0.49200492 | H22: 400 | I22: 2000 | J22: =D22*I22 -> 12000
A23: 21
A24: 22
A25: 23
F26: =SUM(F3:F14) -> 54446 | J26: =SUM(J3:J14) -> 81000
C29: 1046
C30: =C29*18% -> 188.28
C31: =C29+C30 -> 1234.28

Sheet Cake stands and charile 
A2: Sl No | B2: DESCRIPTION | C2: ITEM CODE | D2: Quantity | E2: Our Purchase | F2: Total Purchase Value | G2: ROI on Rent | H2: Rent | I2: Breakage | J2: Value
A3: 1 | C3: SR MBW 1 | D3: 3 | E3: 1180 | F3: =D3*E3 -> 3540 | G3: =H3/E3 -> 0.12711864 | H3: 150 | I3: 1450 | J3: =D3*I3 -> 4350
A4: 2 | B4: Round gold salad / cake stand (plate options extra) | C4: SR MBW 2 | D4: 6 | E4: =950+171 -> 1121 | F4: =D4*E4 -> 6726 | G4: =H4/E4 -> 0.1338091 | H4: 150 | I4: 1350 | J4: =D4*I4 -> 8100
A5: 3 | B5: Gold and white cake stand | C5: SR MBW 3 | D5: 4 | E5: 1428 | F5: =D5*E5 -> 5712 | G5: =H5/E5 -> 0.35014006 | H5: 500 | I5: 2000 | J5: =D5*I5 -> 8000

Sheet mirrorware for buffets 
A2: S.No | B2: Item Code | C2: Images | D2: Particular | E2: Qty of each unit | F2: Our Purchase | G2: total Purchase value | H2: ROI on Rent | I2: Rent per Unit | J2: Breakage | K2: Value
B3: MIRROR
A4: 1 | B4: SR GMRB 1 | D4: Brown beveled mirror Large 18inch Round | E4: 3 | F4: 876 | G4: =F4*E4 -> 2628 | H4: =I4/F4 -> 0.34246575 | I4: 300 | J4: 1400 | K4: =E4*J4 -> 4200
A5: 2 | B5: SR GMRB 2 | D5: Brown beveled Mirror Mid 15inch Round | E5: 1 | F5: 805 | G5: =F5*E5 -> 805 | H5: =I5/F5 -> 0.31055901 | I5: 250 | J5: 1200 | K5: =E5*J5 -> 1200
A6: 3 | B6: SR GMRB 3 | D6: Brown beveled mirror Small 12 inch Round | E6: 1 | F6: 484 | G6: =F6*E6 -> 484 | H6: =I6/F6 -> 0.41322314 | I6: 200 | J6: 1000 | K6: =E6*J6 -> 1000
A7: 4 | B7: SR-GMR 1 | D7: Beveled mirror Large 16 x 21 inch Uneven | E7: 1 | F7: 1287 | G7: =F7*E7 -> 1287 | H7: =I7/F7 -> 0.23310023 | I7: 300 | J7: 1500 | K7: =E7*J7 -> 1500
A8: 5 | B8: SR-GMR 2 | D8: Beveled Mirror Mid 15 x 20 Uneven | E8: 1 | F8: 1263 | G8: =F8*E8 -> 1263 | H8: =I8/F8 -> 0.19794141 | I8: 250 | J8: 1400 | K8: =E8*J8 -> 1400
A9: 6 | B9: SR-GMR 3 | D9: Beveled mirror Small 14 x 19 inch Uneven | E9: 1 | F9: 1239 | G9: =F9*E9 -> 1239 | H9: =I9/F9 -> 0.1614205 | I9: 200 | J9: 1300 | K9: =E9*J9 -> 1300
B10: TRANSPARENT | F10: 1 | G10: =F10*E10 -> 0 | H10: =I10/F10 -> 0
A11: 1 | B11: SR-GAT 1 | D11: Transparent beveled glass Large 9 x28 Arrow | E11: 3 | F11: 1086 | G11: =F11*E11 -> 3258 | H11: =I11/F11 -> 0.27624309 | I11: 300 | J11: 1400 | K11: =E11*J11 -> 4200
A12: 2 | B12: SR-GAT 2 | D12: Transparent beveled glass Mid 9 x 24 Arrow | E12: 1 | F12: 909 | G12: =F12*E12 -> 909 | H12: =I12/F12 -> 0.2750275 | I12: 250 | J12: 1200 | K12: =E12*J12 -> 1200
A13: 3 | B13: SR-GAT 3 | D13: Transparent beveled glass Small 9 x 20 Arrow | E13: 1 | F13: 862 | G13: =F13*E13 -> 862 | H13: =I13/F13 -> 0.23201856 | I13: 200 | J13: 1000 | K13: =E13*J13 -> 1000
A14: 4 | B14: SR-GOT1 | D14: Transparent beveled glass Large 12 x24 Oval | E14: 1 | F14: 944 | G14: =F14*E14 -> 944 | H14: =I14/F14 -> 0.31779661 | I14: 300 | J14: 1400 | K14: =E14*J14 -> 1400
A15: 5 | B15: SR-GOT 2 | D15: Transparent beveled glass Mid 12 x 20 Oval | E15: 3 | F15: 897 | G15: =F15*E15 -> 2691 | H15: =I15/F15 -> 0.2787068 | I15: 250 | J15: 1200 | K15: =E15*J15 -> 3600
A16: 6 | B16: SR-GOT 3 | D16: Transparent beveled glass Small 12 x 16 Oval | E16: 1 | F16: 720 | G16: =F16*E16 -> 720 | H16: =I16/F16 -> 0.27777778 | I16: 200 | J16: 1000 | K16: =E16*J16 -> 1000
A17: 7 | B17: SR-GA 1 | D17: Brown beveled glass Large 9 x28 Arrow | E17: 1 | F17: 1062 | G17: =F17*E17 -> 1062 | H17: =I17/F17 -> 0.28248588 | I17: 300 | J17: 1400 | K17: =E17*J17 -> 1400
A18: 8 | B18: SR-GA 2 | D18: Brown beveled glass Mid 9 x 24 Arrow | E18: 1 | F18: 885 | G18: =F18*E18 -> 885 | H18: =I18/F18 -> 0.28248588 | I18: 250 | J18: 1200 | K18: =E18*J18 -> 1200
A19: 9 | B19: SR-GA 3 | D19: Brown beveled glass Small 9 x 20 Arrow | E19: 3 | F19: 838 | G19: =F19*E19 -> 2514 | H19: =I19/F19 -> 0.23866348 | I19: 200 | J19: 1000 | K19: =E19*J19 -> 3000
A20: 10 | B20: SR-GWBP -1 | D20: Brown beveled glass Small 20CM ( 2 in shade White , sky blue , pink) | E20: 9 | F20: 900 | G20: =F20*E20 -> 8100 | H20: =I20/F20 -> 0.16666667 | I20: 150 | J20: 1000 | K20: =E20*J20 -> 9000
G21: =SUM(G4:G20) -> 29651 | H21: =SUM(H4:H19)/15 -> 0.27466104 | K21: =SUM(K4:K20) -> 37600

Sheet Plates 
A2: Sr No | B2: Code | C2: Discription | D2: Quantity | E2: Our Purchase | F2: Total Purchase .VALUE | G2: ROI on Rent | H2: Rent | I2: Breakege | J2: Value
A3: 1 | B3: SR DIN P 1 | C3: MODERN GREEN DINNER PLATE | D3: 300 | E3: 365 | F3: =D3*E3 -> 109500 | G3: =H3/E3 -> 0.10958904 | H3: 40 | I3: 365 | J3: =D3*I3 -> 109500
A4: 2 | B4: SR SID P 1 | C4: MODERN GREEN SIDE PLATE | D4: 312 | E4: 235 | F4: =D4*E4 -> 73320 | G4: =H4/E4 -> 0.12765957 | H4: 30 | I4: 235 | J4: =D4*I4 -> 73320
A5: 3 | B5: SR DIN B 1 | C5: MODERN GREEN KATORI (190ml) | D5: 336 | E5: 175 | F5: =D5*E5 -> 58800 | G5: =H5/E5 -> 0.11428571 | H5: 20 | I5: 175 | J5: =D5*I5 -> 58800
A6: 4 | B6: SR DES 1 | C6: Black rim flat plate (18mm) | D6: 24 | E6: 595 | F6: =D6*E6 -> 14280 | G6: =H6/E6 -> 0.084033613 | H6: 50 | I6: 700 | J6: =D6*I6 -> 16800
F7: =SUM(F3:F6) -> 255900 | G7: =(G3+G4+G5+G6)/4 -> 0.10889199 | J7: =SUM(J3:J6) -> 258420

Sheet Cutlury 
A2: S.No | B2: DESIGN NAME | C2: ITEM CODE | D2: ITEM DESCRIPTION | E2: Qty | F2: Rent | G2: Breakage | H2: Value | I2: Rent %
A3: 1 | B3: DURBAN | C3: SR-D CUT 1 | D3: Durban Mocca Spoon L: 114.00 mm ; T: 2.50 mm | E3: 60 | F3: 20 | G3: 100 | H3: =E3*G3 -> 6000 | I3: =F3/G3 -> 0.2
A4: 2 | C4: SR-D CUT 2 | D4: Durban Tea Spoon L: 146.00 mm ; T: 3.00 mm | E4: =120+36+36 -> 192 | F4: 20 | G4: 100 | H4: =E4*G4 -> 19200 | I4: =F4/G4 -> 0.2
A5: 3 | C5: SR-D CUT 3 | D5: Durban Dinner Spoon L: 189.00 mm ; T: 3.50 mm | E5: 360 | F5: 30 | G5: 150 | H5: =E5*G5 -> 54000 | I5: =F5/G5 -> 0.2
A6: 4 | C6: SR-D CUT 4 | D6: Durban Dinner Fork L: 189.00 mm ; T: 3.50 mm | E6: 360 | F6: 30 | G6: 150 | H6: =E6*G6 -> 54000 | I6: =F6/G6 -> 0.2
A7: 5 | C7: SR-D CUT 5 | D7: Durban Dinner Knife L: 205.00 mm ; T: 7.00 mm | E7: 120 | F7: 30 | G7: 180 | H7: =E7*G7 -> 21600 | I7: =F7/G7 -> 0.16666667
A8: 6 | C8: SR-D CUT 6 | D8: Durban Soup Spoon L: 187.40 mm ; T: 3.50 mm | E8: 120 | F8: 30 | G8: 200 | H8: =E8*G8 -> 24000 | I8: =F8/G8 -> 0.15
A9: 7 | C9: SR-D CUT 7 | D9: Durban Serving Spoon L: 217.70 mm ; T: 4.00 mm | E9: 48 | F9: 40 | G9: 200 | H9: =E9*G9 -> 9600 | I9: =F9/G9 -> 0.2
A10: 8 | C10: SR-D CUT 8 | D10: Durban Serving Fork L: 218.20 mm ; T: 4.00 mm | E10: 48 | F10: 40 | G10: 200 | H10: =E10*G10 -> 9600 | I10: =F10/G10 -> 0.2
H11: =SUM(H3:H10) -> 198000 | I11: =(I3+I4+I5+I6+I7+I8+I9+I10)/8 -> 0.18958333
A14: S.No | B14: DESIGN NAME | C14: ITEM CODE | D14: ITEM DESCRIPTION | E14: Qty | F14: Rent | G14: Breakage | H14: Value | I14: Rent %
A15: 1 | B15: DURBAN- Rose Gold | C15: SR-DG CUT 1 | D15: Durban Mocca Spoon L: 114.00 mm ; T: 2.50 mm | E15: =48 -> 48 | F15: 20 | G15: 100 | H15: =E15*G15 -> 4800 | I15: =F15/G15 -> 0.2
A16: 2 | C16: SR-DG CUT 2 | D16: Durban Tea Spoon L: 146.00 mm ; T: 3.00 mm | E16: =60 -> 60 | F16: 20 | G16: 100 | H16: =E16*G16 -> 6000 | I16: =F16/G16 -> 0.2
A17: 3 | C17: SR-DG CUT 3 | D17: Durban Dinner Spoon L: 189.00 mm ; T: 3.50 mm | E17: =180 -> 180 | F17: 30 | G17: 150 | H17: =E17*G17 -> 27000 | I17: =F17/G17 -> 0.2
A18: 4 | C18: SR-DG CUT 4 | D18: Durban Dinner Fork L: 189.00 mm ; T: 3.50 mm | E18: =180 -> 180 | F18: 30 | G18: 150 | H18: =E18*G18 -> 27000 | I18: =F18/G18 -> 0.2
A19: 5 | C19: SR-DG CUT 5 | D19: Durban Dinner Knife L: 205.00 mm ; T: 7.00 mm | E19: =96 -> 96 | F19: 30 | G19: 180 | H19: =E19*G19 -> 17280 | I19: =F19/G19 -> 0.16666667
A20: 6 | C20: SR-DG CUT 6 | D20: Durban Soup Spoon L: 187.40 mm ; T: 3.50 mm | E20: =60 -> 60 | F20: 30 | G20: 200 | H20: =E20*G20 -> 12000 | I20: =F20/G20 -> 0.15
A21: 7 | C21: SR-DG CUT 7 | D21: Durban Serving Spoon L: 217.70 mm ; T: 4.00 mm | E21: 24 | F21: 40 | G21: 200 | H21: =E21*G21 -> 4800 | I21: =F21/G21 -> 0.2
A22: 8 | C22: SR-DG CUT 8 | D22: Durban Serving Fork L: 218.20 mm ; T: 4.00 mm | E22: 24 | F22: 40 | G22: 200 | H22: =E22*G22 -> 4800 | I22: =F22/G22 -> 0.2
H23: =SUM(H15:H22) -> 103680 | I23: =(I15+I16+I17+I18+I19+I20+I21+I22)/8 -> 0.18958333
A25: S.No | B25: DESIGN NAME | C25: ITEM CODE | D25: Qty | E25: Actual Purchase With GST | F25: Rent | G25: Breakage | H25: Value | I25: Rent %
A26: 1 | B26: Dubai rose gold Cake kinfe set of 2 | C26: SR -DBX CAKE 1 | D26: 2 | E26: 399 | F26: 50 | G26: 500 | H26: =E26*D26 -> 798 | I26: =F26/E26 -> 0.12531328
A27: 2 | B27: Mini gold soup spoon | C27: SR -DBX SOUP 1 | D27: 20 | E27: =2345/20 -> 117.25 | F27: 50 | G27: 200 | H27: =D27*E27 -> 2345 | I27: =F27/E27 -> 0.42643923
A28: 3 | B28: Long gold heart spoon | C28: SR -DBX long spoon 1 | D28: 12 | E28: 29 | F28: 30 | G28: 50 | H28: =D28*E28 -> 348 | I28: =F28/E28 -> 1.0344828
A29: 4 | B29: Long gold flower spoon 1 | C29: SR -DBX long spoon 2 | D29: 12 | E29: 29 | F29: 30 | G29: 50 | H29: =D29*E29 -> 348 | I29: =F29/E29 -> 1.0344828
A30: 5 | B30: Long gold flower spoon 2 | C30: SR -DBX long spoon 3 | D30: 12 | E30: 29 | F30: 30 | G30: 50 | H30: =D30*E30 -> 348 | I30: =F30/E30 -> 1.0344828
A31: 6 | B31: Long gold flower spoon 3 | C31: SR -DBX long spoon 4 | D31: 12 | E31: 29 | F31: 30 | G31: 50 | H31: =D31*E31 -> 348 | I31: =F31/E31 -> 1.0344828
A34: S.No | B34: DESIGN NAME | C34: ITEM CODE | D34: Qty | E34: Actual Purchase With GST | F34: Rent | G34: Breakage | H34: Value | I34: Rent %
A35: 1 | B35: Gold Small Fork | C35: SR-SG-F 1 | D35: 42 | E35: 80 | F35: 20 | G35: 150 | H35: =G35*D35 -> 6300 | I35: =F35/G35 -> 0.13333333
A36: 2 | B36: Silver Small Fork | C36: SR-SS-F 2 | D36: 42 | E36: 30 | F36: 20 | G36: 150 | H36: =G36*D36 -> 6300 | I36: =F36/G36 -> 0.13333333

Sheet Others Equpments 
A2: Sr No | B2: Code | C2: Discription | D2: Quantity | E2: Our Purchase | F2: Total Purchase .VALUE | G2: ROI on Rent | H2: Rent | I2: Breakege | J2: Value
A3: 1 | B3: SR CHF -1 | C3: Casoral with warmer 6Ltr | D3: 12 | E3: 18101 | F3: =E3*D3 -> 217212 | G3: =H3/E3 -> 0.027622783 | H3: 500 | I3: 19000 | J3: =D3*I3 -> 228000
A4: 2 | B4: SR LAD 1 | C4: ladel | D4: 12 | E4: 814 | F4: =E4*D4 -> 9768 | G4: =H4/E4 -> 0.18427518 | H4: 150 | I4: 1000 | J4: =D4*I4 -> 12000
A5: 3 | B5: SR LAD 2 | C5: ladel | D5: 12 | E5: 814 | F5: =E5*D5 -> 9768 | G5: =H5/E5 -> 0.18427518 | H5: 150 | I5: 1000 | J5: =D5*I5 -> 12000
A6: 4 | B6: SR T-1 | C6: SS Utility Tong | D6: 16 | E6: =92+I22 -> 108.92 | F6: =E6*D6 -> 1742.72 | G6: =H6/E6 -> 0.45905252 | H6: 50 | I6: 150 | J6: =D6*I6 -> 2400
A7: 5 | B7: SR T-2 | C7: SS Sugar Tong | D7: 12 | E7: =45+8 -> 53 | F7: =E7*D7 -> 636 | G7: =H7/E7 -> 0.56603774 | H7: 30 | I7: 100 | J7: =D7*I7 -> 1200
A8: 6 | B8: SR STR-1 | C8: Serving Tray SQR 16 inch | D8: 3 | E8: =216+I22 -> 232.92 | F8: =E8*D8 -> 698.76 | G8: =H8/E8 -> 0.42933196 | H8: 100 | I8: 300 | J8: =D8*I8 -> 900
A9: 7 | B9: SR STR-2 | C9: Serving Tray SQR 18inch | D9: 3 | E9: =239+I22 -> 255.92 | F9: =E9*D9 -> 767.76 | G9: =H9/E9 -> 0.48843389 | H9: 125 | I9: 350 | J9: =D9*I9 -> 1050
A10: 8 | B10: SR STR-3 | C10: Serving Tray Round 16 inch | D10: 3 | E10: =225+I22 -> 241.92 | F10: =E10*D10 -> 725.76 | G10: =H10/E10 -> 0.51669974 | H10: 125 | I10: 350 | J10: =D10*I10 -> 1050
A11: 9 | B11: SR STR-4 | C11: Serving Tray Round 14 inch | D11: 3 | E11: =144+I22 -> 160.92 | F11: =E11*D11 -> 482.76 | G11: =H11/E11 -> 0.6214268 | H11: 100 | I11: 300 | J11: =D11*I11 -> 900
A12: 10 | B12: SR JD-1 | C12: Juice Dispenser | D12: 3 | E12: =2115+I22 -> 2131.92 | F12: =E12*D12 -> 6395.76 | G12: =H12/E12 -> 0.32834253 | H12: 700 | I12: 3000 | J12: =D12*I12 -> 9000
A13: 11 | B13: SR ST-1 | C13: Soup Tarean | D13: 4 | E13: =2430+I22 -> 2446.92 | F13: =E13*D13 -> 9787.68 | G13: =H13/E13 -> 0.28607392 | H13: 700 | I13: 3500 | J13: =D13*I13 -> 14000
A14: 12 | B14: SR SUP LAD-1 | C14: Soup Laddle | D14: 4 | E14: =94+I22 -> 110.92 | F14: =E14*D14 -> 443.68 | G14: =H14/E14 -> 0.90155067 | H14: 100 | I14: 500 | J14: =D14*I14 -> 2000
A15: 13 | B15: SR NPH-1 | C15: Name Plate Holder | D15: 50 | F15: =E15*D15 -> 0 | G15: =H15/E15 -> #DIV/0! | H15: 20 | I15: 100 | J15: =D15*I15 -> 5000
F16: =SUM(F3:F15) -> 258428.88 | J16: =SUM(J3:J15) -> 289500
I22: =94*18% -> 16.92

Sheet Tea and coffee sets
A1: Sr No | B1: Code | C1: Discription | D1: Quantity | E1: Our Purchase | F1: Total Purchase .VALUE | G1: ROI on Rent | H1: Rent | I1: Breakege | J1: Value
A2: 1 | B2: SR TEA 1 | C2: Asain tea set with 6 cups and 1 pot (Red) | D2: 2 | E2: 1700 | F2: =E2*D2 -> 3400 | G2: =H2/E2 -> 0.35294118 | H2: 600 | I2: 3500 | J2: =D2*I2 -> 7000
