Workbook
Name Cash_Minimum: '[1]Cash flow forecast'!$J$4
Name Start_Date: #REF!

Sheet capex and accounts summary 
A1: Share holding | B1: =B15 -> 6334414 | C1: Total needed Investment | D1: Invested | E1: Balance to Invest | F1: % | H1: CCG Purchase
A2: Samir | B2: 0.74 | C2: =B1*74% -> 4687466.4 | D2: ='SAMIR CAPEX AS PER BANK'!G102+'SAMIR CAPEX AS PER BANK'!G104+'SAMIR CAPEX AS PER BANK'!G105+'SAMIR CAPEX AS PER BANK'!G106+'SAMIR CAPEX AS PER BANK'!G107+'SAMIR CAPEX AS PER BANK'!G108 -> 4092357.6 | E2: =C2-D2 -> 595108.78 | F2: =D2/C2 -> 0.87304255 | I2: Actual including GST | J2: Paid
A3: Karan | B3: 0.26 | C3: =B15*26% -> 1646947.6 | D3: ='KARAN CAPEX AS PER BANK'!F27+'KARAN CAPEX AS PER BANK'!F28 -> 710000 | E3: =C3-D3 -> 936947.64 | F3: =D3/C3 -> 0.43110053 | H3: Harbour Aritvo , Selite , Rona | I3: 593684
A4: Total | C4: =SUM(C2:C3) -> 6334414 | D4: =SUM(D2:D3) -> 4802357.6 | E4: =SUM(E2:E3) -> 1532056.4 | H4: Thanor Pottery | I4: 146318.21
H5: Viraj Nirman | I5: 861477 | J5: =200000+150000+100000 -> 450000
H6: SK Manekia ( Cutlury ) | I6: 204016 | J6: 204016 | K6: Paid in full
B7: Total Capex | C7: Pending as of May 2025 | H7: SK Manekia ( Green dinner set) | I7: 202407 | J7: 202407 | K7: Paid in full
A8: Legal | B8: ='Accounts against capex'!D15 -> 198220 | C8: 0 | H8: Neeti Utyog | I8: 326683
A9: Working Cap Dec to March | B9: ='Sal and fix working cap cost '!B25+'Sal and fix working cap cost '!C25+'Sal and fix working cap cost '!D25+'Sal and fix working cap cost '!E25 -> 374823.8 | C9: 0
A10: Assets | B10: ='Accounts against capex'!C39 -> 1465575 | C10: 0 | H10: Total Others | I10: =SUM(I3:I9) -> 2334585.2 | J10: =SUM(J3:J9) -> 856423
A11: Civil | B11: ='Accounts against capex'!C43 -> 1605000 | C11: 0 | H11: Balance due | I11: =I10-J10 -> 1478162.2
A12: Ops & Office Supply Less Working Cap | B12: ='Accounts against capex'!C53 -> 168213
A13: Others | B13: ='Accounts against capex'!C61 -> 187997
A14: CCG | B14: =I10 -> 2334585.2 | C14: =I11 -> 1478162.2
A15: Subtotal | B15: =SUM(B8:B14) -> 6334414 | C15: =SUM(C8:C14) -> 1478162.2

Sheet KARAN CAPEX AS PER BANK
A2: SWITCH RENTAL SERVICES LLP
A3: CHOKSEY,MANSION SHAHID,BHAGAT SINGH RD
A4: BAUARD ESTATE ANTP HILL
A5: MUMBAI
A6: E-Mail : samir@switchrental.in
A7: Karan Arjandas Khiani (Loans)
A8: Ledger Account
A11: 1-Apr-24 to 31-Mar-26
A12: Date | B12: Particulars | D12: Vch Type | E12: Vch No. | F12: Debit | G12: Credit
A13: 45406 | B13: By | C13: LLP Formation Expenses | D13: Journal | E13: 170 | G13: 11000
A14: 45471 | B14: By | C14: Karan Arjandas Khiani ( 24% Shares) | D14: Journal | E14: 3 | G14: 37000
A15: 45541 | B15: By | C15: Icici bank - 104305003604 | D15: Receipt | E15: 5 | G15: 501
A16: 45541 | B16: By | C16: Icici bank - 104305003604 | D16: Receipt | E16: 7 | G16: 101
A17: 45549 | B17: To | C17: Cash | D17: Payment | E17: 20 | F17: 602
A18: 45575 | B18: By | C18: Icici bank - 104305003604 | D18: Receipt | E18: 10 | G18: 50000
A19: 45735 | B19: By | C19: Icici bank - 104305003604 | D19: Receipt | E19: 68 | G19: 100000
A20: 45737 | B20: By | C20: Icici bank - 104305003604 | D20: Receipt | E20: 71 | G20: 50000
A21: 45765 | B21: By | C21: Icici bank - 104305003604 | D21: Receipt | E21: 12 | G21: 150000
A22: 45780 | B22: By | C22: Icici bank - 104305003604 | D22: Receipt | E22: 20 | G22: 150000
A23: 602 | G23: 548602
B24: To | C24: Closing Balance | D24: 548000
A25: 548602 | G25: 548602
F27: 610000
C28: 13th MAY | F28: 100000

Sheet SAMIR CAPEX AS PER BANK
A1: SWITCH RENTAL SERVICES LLP
A2: CHOKSEY,MANSION SHAHID,BHAGAT SINGH RD
A3: BAUARD ESTATE ANTP HILL
A4: MUMBAI
A5: E-Mail : samir@switchrental.in
A6: Samir Rajanc Chhabria (Loan)
A7: Ledger Account
A10: 1-Apr-24 to 31-May-25
A11: Date | B11: Particulars | D11: Vch Type | E11: Vch No. | F11: Debit | G11: Credit
A12: 45406 | B12: By | C12: LLP Formation Expenses | D12: Journal | E12: 170 | G12: 11000
A13: 45482 | B13: By | C13: Icici bank - 104305003604 | D13: Receipt | E13: 2 | G13: 11
A14: 45482 | B14: By | C14: Icici bank - 104305003604 | D14: Receipt | E14: 3 | G14: 75000
A15: 45482 | B15: To | C15: Samir Rajan Chhabria ( 74% Share) | D15: Journal | E15: 5 | F15: 38000
A16: 45516 | B16: By | C16: Office Exp | D16: Journal | E16: 172 | G16: 28000
A17: 45518 | B17: By | C17: Icici bank - 104305003604 | D17: Receipt | E17: 4 | G17: 100000
A18: 45523 | B18: By | C18: Office Exp | D18: Journal | E18: 173 | G18: 18000
A19: 45549 | B19: By | C19: Cash | D19: Receipt | E19: 14 | G19: 2000
A20: 45556 | B20: By | C20: Icici bank - 104305003604 | D20: Receipt | E20: 8 | G20: 50000
A21: 45567 | B21: By | C21: Suresh S Pawar | D21: Journal | E21: 152 | G21: 50000
A22: 45569 | B22: By | C22: Icici bank - 104305003604 | D22: Receipt | E22: 9 | G22: 150000
A23: 45576 | B23: By | C23: Icici bank - 104305003604 | D23: Receipt | E23: 11 | G23: 80000
A24: 45587 | B24: By | C24: Icici bank - 104305003604 | D24: Receipt | E24: 12 | G24: 100000
A25: 45593 | B25: By | C25: Icici bank - 104305003604 | D25: Receipt | E25: 13 | G25: 50000
A26: 45594 | B26: By | C26: Office Exp | D26: Journal | E26: 174 | G26: 12000
A27: 45603 | B27: By | C27: Icici bank - 104305003604 | D27: Receipt | E27: 15 | G27: 100000
... A38: 45650 | B38: By | C38: Office Exp | D38: Journal | E38: 176 | G38: 34300
A39: 45653 | B39: To | C39: Shrenik N Bamb & Associates | D39: Journal | E39: 41 | F39: 30000
A40: 45654 | B40: By | C40: STEC HOTELWARES LLP | D40: Journal | E40: 75 | G40: 119168
A41: 45654 | B41: By | C41: Icici bank - 104305003604 | D41: Receipt | E41: 23 | G41: 30000
A42: 45657 | B42: By | C42: Icici bank - 104305003604 | D42: Receipt | E42: 24 | G42: 20000
A43: 45658 | B43: By | C43: Rebel Foods Private Limited | D43: Journal | E43: 73 | G43: 3235.06
A44: 45658 | B44: By | C44: Cash | D44: Receipt | E44: 81 | G44: 10000
A45: 45658 | B45: By | C45: Cash | D45: Receipt | E45: 82 | G45: 1416
A46: 45659 | B46: By | C46: Icici bank - 104305003604 | D46: Receipt | E46: 25 | G46: 20000
A47: 45660 | B47: By | C47: Icici bank - 104305003604 | D47: Receipt | E47: 26 | G47: 20000
A48: 45660 | B48: By | C48: Tata Teleservices Maharashtra Limited | D48: Journal | E48: 77 | G48: 47200
A49: 45664 | B49: By | C49: Etrade Marketing Pvt. Ltd. | D49: Journal | E49: 80 | G49: 422
A50: 45664 | B50: By | C50: Infiniti Retail Limited (Croma) | D50: Journal | E50: 69 | G50: 33962.29
A51: 45666 | B51: By | C51: Icici bank - 104305003604 | D51: Receipt | E51: 27 | G51: 70000
A52: 45668 | B52: To | C52: Shrenik N Bamb & Associates | D52: Journal | E52: 37 | F52: 4700
...

Sheet Accounts against capex
A1: Legal | B1: Paid by | C1: Total | D1: Paid | E1: Balance
A2: Licensee Obtaining Cost if any | B2: Company | C2: 0 | D2: 0 | E2: =C2-D2 -> 0
A3: Registration of company | B3: Samir Personal | C3: 11000 | D3: 11000 | E3: =C3-D3 -> 0
A4: Registration of company | B4: Karan Personal | C4: 11000 | D4: 11000 | E4: =C4-D4 -> 0
A5: Registration ( change of address and holding) | B5: Company | C5: =D5 -> 11900 | D5: 11900 | E5: =C5-D5 -> 0
A6: Registration and Stamp Duty ( twice) | B6: Samir Personal | C6: 26000 | D6: =13000+13000 -> 26000 | E6: =C6-D6 -> 0
A7: Shop & Establisment license | B7: Samir Personal | C7: 5800 | D7: 5800 | E7: =C7-D7 -> 0
A8: GST fee | B8: Company | C8: 14750 | D8: 14750 | E8: =C8-D8 -> 0
A9: CA fees | B9: Company | C9: =6900+27570 -> 34470 | D9: =C9 -> 34470 | E9: =C9-D9 -> 0
A10: Lawer fee for all documention | B10: Company | C10: 37000 | D10: =C10 -> 37000 | E10: =C10-D10 -> 0
A11: Fire Complience fee | B11: Samir Personal | C11: 29000 | D11: 29000 | E11: =C11-D11 -> 0
A12: Fire extenvisher ( 20kg) 4 units | B12: Company | C12: 12500 | D12: 12500 | E12: =C12-D12 -> 0
A13: Komal KYC Fees | B13: Company | C13: 1800 | D13: 1800 | E13: =C13-D13 -> 0
A14: True copy for documents ( twice) | B14: Samir Personal | C14: 3000 | D14: 3000 | E14: =C14-D14 -> 0
A15: Total | C15: =SUM(C2:C14) -> 198220 | D15: =SUM(D3:D14) -> 198220 | E15: =SUM(E2:E14) -> 0
A16: Assets
A17: Rental Deposits 3 months (Refundable) | B17: Company | C17: 150000 | D17: 150000 | E17: =C17-D17 -> 0
A18: Branding and qulatrals | B18: Company | C18: =3700+34611+6300 -> 44611 | D18: =C18 -> 44611 | E18: =C18-D18 -> 0
A19: Uniforms | B19: Samir Personal | C19: 3750 | D19: 3750 | E19: =C19-D19 -> 0
A20: Dish washer with Ss trolley extra | B20: Company | C20: 449570 | D20: =C20 -> 449570 | E20: =C20-D20 -> 0
A21: Office décor | B21: Samir Personal | C21: =7990+1799+739+899 -> 11427 | D21: 11427 | E21: =C21-D21 -> 0
A22: Water softner | B22: Company | C22: 75000 | D22: 75000 | E22: =C22-D22 -> 0
A23: Racks | B23: Company | C23: 334058 | D23: 334058 | E23: =C23-D23 -> 0
A24: Nilkamal tote boxes | B24: Company | C24: 55110 | D24: 55110 | E24: =C24-D24 -> 0
A25: Tote boxes for all Glassware stec ( Paid with HDFC CC) | B25: personal samir | C25: =119168-5000-850-400 -> 112918 | D25: =C25 -> 112918 | E25: =C25-D25 -> 0
A26: Added tote boxes ( 10 glass racks and 25 extenders ) + Dustbin , floor mat , cuttlury rack | B26: personal samir | C26: 24845 | D26: 24845 | E26: =C26-D26 -> 0
A27: Kitchen mats ( Paid with HDFC CC) | B27: personal samir | C27: 850 | D27: 850 | E27: =C27-D27 -> 0
A28: Trolley ( Paid with HDFC CC) | B28: personal samir | C28: 5000 | D28: 5000 | E28: =C28-D28 -> 0
A29: glass rasck from Janta (sample 1 unit) | B29: personal samir | C29: 2000 | D29: 2000 | E29: =C29-D29 -> 0
A30: CCG | B30: Personal Karan / company | C30: 0 | D30: 0 | E30: =C30-D30 -> 0
A31: Mirror & Glass for buffet ware | B31: Company | C31: 14147 | D31: =C31 -> 14147 | E31: =C31-D31 -> 0
A32: Micro | B32: Samir Personal | C32: =5690 -> 5690 | D32: 5690 | E32: =C32-D32 -> 0
A33: Mobil phone (2) | B33: Samir Personal | C33: 25000 | D33: 25000 | E33: =C33-D33 -> 0
A34: Kettle | B34: Samir Personal | C34: =599 -> 599 | D34: 599 | E34: =C34-D34 -> 0
A35: Lap top | B35: Samir Personal | C35: 34000 | D35: 34000 | E35: =C35-D35 -> 0
A36: printer with photo copy and scanner | B36: Samir Personal | C36: 5200 | D36: 5200 | E36: =C36-D36 -> 0
A37: Internet hardware | B37: Company | C37: 7800 | D37: 7800 | E37: =C37-D37 -> 0
A38: AC | B38: Company | C38: 104000 | D38: =104000 -> 104000 | E38: =C38-D38 -> 0
A39: Total | C39: =SUM(C17:C38) -> 1465575 | D39: =SUM(D17:D38) -> 1465575 | E39: =SUM(E18:E38) -> 0
A40: Civil
...

Sheet PnL Jan 25 to Mar 26
A1: Months marked in (Red are acutal in Green is current , in Black is forecast )
A2: 2025
A3: Revenue flow (Part A) | B3: Jan | C3: Feb | D3: March | E3: April | F3: May | G3: June | H3: July | I3: Aug | J3: Sep | K3: Oct | L3: Nov | M3: Dec | N3: Jan | O3: Feb | P3: March | Q3: TOTAL 25-26
A4: Business days | B4: 15 | C4: 23 | D4: 26 | E4: =30-4 -> 26 | F4: =30-4 -> 26 | G4: =30-4 -> 26 | H4: =30-4 -> 26 | I4: =30-4 -> 26 | J4: =30-4 -> 26 | K4: =30-4 -> 26 | L4: =30-4 -> 26 | ... N4: =30-4 -> 26 | O4: =28-4 -> 24 | P4: =30-4 -> 26
A5: BUDGET NET REV | B5: 125000 | C5: 150000 | D5: 175000 | E5: 200000 | F5: 220000 | G5: 250000 | H5: 300000 | I5: 325000 | J5: 400000 | K5: 500000 | L5: 600000 | M5: 700000 | N5: 800000 | O5: 600000 | P5: 550000 | Q5: =SUM(B5:P5) -> 5895000
A6: Revenue Acutal | B6: ='[2]JAN 25'!$G$32+'[2]JAN 25'!$H$32 -> 72314 | C6: ='[2]FEB 25'!$I$33 -> 37168 | D6: ='[2]March 25'!$G$32 -> 131137 | E6: ='[2]April 25 '!$G$33 -> 208715 | F6: ='[2]May 25'!$G$24 -> 229200 | G6: ='[2]June 25'!$G$25 -> 0 | H6: =H5 -> 300000 | I6: =I5 -> 325000 | J6: =J5 -> 400000 | K6: =K5 -> 500000 | L6: =L5 -> 600000 | M6: =M5 -> 700000 | N6: =25000*N4 -> 650000 | O6: =O5 -> 600000 | P6: =P5 -> 550000 | Q6: =SUM(E6:P6) -> 5062915
A7: Breakage rev Acutal | C7: ='[2]FEB 25'!$H$33 -> 1260 | D7: ='[2]March 25'!$H$32 -> 10564 | E7: ='[2]April 25 '!$H$33 -> 23445 | F7: ='[2]May 25'!$H$24 -> 18470 | G7: ='[2]June 25'!$H$25 -> 0
A8: Discount Actual | B8: ='[2]JAN 25'!$I$32 -> 5476.4 | C8: ='[2]FEB 25'!$J$33 -> 5874 | D8: ='[2]March 25'!$I$32 -> 11563.25 | E8: ='[2]April 25 '!$I$33 -> 19575 | F8: ='[2]May 25'!$I$24 -> 13810 | G8: ='[2]June 25'!$I$25 -> 0 | H8: =H6*5% -> 15000 | I8: =I6*5% -> 16250 | J8: =J6*5% -> 20000 | K8: =K6*5% -> 25000 | L8: =L6*5% -> 30000 | M8: =M6*5% -> 35000 | N8: =N6*5% -> 32500 | O8: =O6*5% -> 30000 | P8: =P6*5% -> 27500 | Q8: =SUM(E8:P8) -> 264635
A10: Total Net Rev - ( All calclutions will be done on this figure) | B10: =B6-B8 -> 66837.6 | C10: =C6+C7-C8-C9 -> 32554 | D10: =D6+D7-D8 -> 130137.75 | E10: =E6+E7-E8-E9 -> 212585 | F10: =F6+F7-F8 -> 233860 | G10: =G6-G8 -> 0 | H10: =H6-H8 -> 285000 | I10: =I6-I8 -> 308750 | J10: =J6-J8 -> 380000 | K10: =K6-K8 -> 475000 | L10: =L6-L8 -> 570000 | M10: =M6-M8 -> 665000 | N10: =N6-N8 -> 617500 | ... P10: =P6-P8 -> 522500
A11: Add GST | B11: ='[2]JAN 25'!$K$32 -> 11024.568 | C11: =C10*18% -> 5859.72 | D11: ='[2]March 25'!$K$32 -> 23424.795 | E11: ='[2]March 25'!$K$32 -> 23424.795 | F11: ='[2]May 25'!$K$24 -> 42094.8 | G11: =G10*18% -> 0 | H11: =H10*18% -> 51300 | I11: =I10*18% -> 55575 | J11: =J10*18% -> 68400 | K11: =K10*18% -> 85500 | L11: =L10*18% -> 102600 | M11: =M10*18% -> 119700 | N11: =N10*18% -> 111150 | ... P11: =P10*18% -> 94050 | Q11: =SUM(E11:P11) -> 856394.59
A12: Grorss Revenue | B12: =B10+B11 -> 77862.168 | C12: =C10+C11 -> 38413.72 | D12: =D10+D11 -> 153562.55 | E12: =E10+E11 -> 236009.8 | F12: =F10+F11 -> 275954.8 | G12: =G10+G11 -> 0 | H12: =H10+H11 -> 336300 | I12: =I10+I11 -> 364325 | ... P12: =P10+P11 -> 616550 | Q12: =SUM(E12:P12) -> 5696589.6
A13: Cost
A14: Fixed
A15: Rent | B15: 0 | C15: 0 | D15: 0 | E15: 0 | F15: 0 | G15: 0 | H15: 0 | I15: 0 | J15: 0 | K15: 0 | L15: =49350-L16 -> 44400 | M15: =49350-M16 -> 44400 | N15: =49350-N16 -> 44400 | O15: =49350-O16 -> 44400 | P15: =49350-P16 -> 44400 | Q15: =SUM(B15:P15) -> 222000
A16: Oulet Rent TDS only | B16: 4950 | C16: 4950 | D16: 4950 | E16: 4950 | F16: 4950 | G16: 4950 | H16: 4950 | I16: 4950 | J16: 4950 | K16: 4950 | L16: 4950 | M16: 4950 | N16: 4950 | O16: 4950 | P16: 4950 | Q16: =SUM(E16:P16) -> 59400
A17: Staff drinking water for drinking water | B17: 250 | C17: 250 | D17: 750 | E17: 750 | F17: 750 | G17: 750 | H17: 750 | I17: 750 | J17: 750 | K17: 750 | L17: 750 | M17: 750 | N17: 750 | O17: 750 | P17: 750 | Q17: =SUM(G17:P17) -> 7500
A18: Salary HO | B18: 4250 | C18: 24000 | D18: =27000+50000+15000 -> 92000 | E18: =27000+50000+15000 -> 92000 | F18: =23500+50000 -> 73500 | G18: =27000+50000+7500 -> 84500 | H18: =27000+50000+15000 -> 92000 | I18: =27000+50000+15000 -> 92000 | J18: =27000+50000+15000 -> 92000 | K18: =27000+50000+15000 -> 92000 | L18: =27000+50000+15000 -> 92000 | M18: =27000+50000+15000 -> 92000 | N18: =27000+50000+15000 -> 92000 | O18: =27000+50000+15000 -> 92000 | P18: =27000+50000+15000 -> 92000 | Q18: =SUM(E18:P18) -> 1078000
A19: Salary Out sourced | B19: 57286 | C19: 56050 | D19: 49232 | E19: 39580 | F19: 30642 | G19: 20650 | H19: =17500*18%+(17500) -> 20650 | I19: =17500*18%+(17500) -> 20650 | J19: =17500*18%+(17500) -> 20650 | K19: =17500*18%+(17500) -> 20650 | L19: =17500*18%+(17500) -> 20650 | M19: =17500*18%+(17500) -> 20650 | N19: =17500*18%+(17500) -> 20650 | O19: =17500*18%+(17500) -> 20650 | P19: =17500*18%+(17500) -> 20650 | Q19: =SUM(E19:P19) -> 276722
A20: Eletricity | B20: 4729 | C20: 6444 | D20: 9709 | E20: 10971 | F20: 8000 | G20: 8000 | H20: 8000 | I20: 8000 | J20: 8000 | K20: 8000 | L20: 8000 | M20: 8000 | N20: 8000 | O20: 8000 | P20: 8000 | Q20: =SUM(E20:P20) -> 98971
A21: Water | B21: 3500 | C21: 3500 | D21: 3500 | E21: 3500 | F21: 3500 | G21: 3500 | H21: 3500 | I21: 3500 | J21: 3500 | K21: 3500 | L21: 3500 | M21: 3500 | N21: 3500 | O21: 3500 | P21: 3500 | Q21: =SUM(E21:P21) -> 42000
A22: Insurance ( Equipment ) | B22: 0 | C22: 0 | D22: 0 | E22: 0 | F22: 0 | G22: 0 | H22: 0 | I22: 0 | J22: 0 | K22: 0 | L22: 0 | M22: 0 | N22: 0 | O22: 0 | P22: 0 | Q22: =SUM(E22:P22) -> 0
A23: Internet | B23: 16000 | C23: 16000 | D23: 16000 | E23: 16000 | F23: 16000 | G23: 16000 | H23: 16000 | I23: 16000 | J23: 16000 | K23: 16000 | L23: 16000 | M23: 2000 | N23: 2000 | O23: 2000 | P23: 2000 | Q23: =SUM(E23:P23) -> 136000
A24: mobile | B24: 850 | C24: 850 | D24: 850 | E24: 827 | F24: 850 | G24: 850 | H24: 850 | I24: 850 | J24: 850 | K24: 850 | L24: 850 | M24: 850 | N24: 850 | O24: 850 | P24: 850 | Q24: =SUM(E24:P24) -> 10177
A25: Total | B25: =SUM(B15:B24) -> 91815 | C25: =SUM(C15:C24) -> 112044 | D25: =SUM(D15:D24) -> 176991 | E25: =SUM(E15:E24) -> 168578 | F25: =SUM(F15:F24) -> 138192 | G25: =SUM(G15:G24) -> 139200 | H25: =SUM(H15:H24) -> 146700 | I25: =SUM(I15:I24) -> 146700 | ... P25: =SUM(P15:P24) -> 177100 | Q25: =SUM(E25:P25) -> 1932270
A26: % of sales from net rev | B26: =B25/B10 -> 1.3737028 | C26: =C25/C10 -> 3.441789 | D26: =D25/D10 -> 1.3600281 | E26: =E25/E12 -> 0.71428391 | F26: =F25/F12 -> 0.50077766 | G26: =G25/G12 -> #DIV/0! | H26: =H25/H12 -> 0.43621766 | I26: =I25/I12 -> 0.40266246 | J26: =J25/J12 -> 0.32716325 | K26: =K25/K12 -> 0.2617306 | L26: =L25/L12 -> 0.28412132 | ... Q26: =Q25/Q12 -> 0.33919768
A27: Semi Variable Operations
A28: Dishwashing supply | B28: 600 | C28: 600 | D28: 600 | E28: 600 | F28: 600 | G28: 600 | H28: 600 | I28: 600 | J28: 600 | K28: 600 | L28: 600 | M28: 600 | N28: 600 | O28: 600 | P28: 600 | Q28: =SUM(E28:P28) -> 7200
A29: House Keeping Supply including WC | B29: 800 | C29: 800 | D29: 800 | E29: 800 | F29: 800 | G29: 800 | H29: 800 | I29: 800 | J29: 800 | K29: 800 | L29: 800 | M29: 800 | N29: 800 | O29: 800 | P29: 800 | Q29: =SUM(E29:P29) -> 9600
A30: Daily staff supply man power | B30: 0 | C30: 0 | D30: 0 | E30: 0 | F30: =2750+1650 -> 4400 | G30: 3500
A31: Pest Control & deep cleaning ( 2 times per month) | B31: 2000 | C31: 2000 | D31: 2000 | E31: 2000 | F31: 2000 | G31: 2000 | H31: 2000 | I31: 2000 | J31: 2000 | K31: 2000 | L31: 2000 | M31: 2000 | N31: 2000 | O31: 2000 | P31: 2000 | Q31: =SUM(E31:P31) -> 24000
A32: Staff Food | B32: 1000 | C32: 1000 | D32: 1000 | E32: 1000 | F32: 1000 | G32: 1000 | H32: 1000 | I32: 1000 | J32: 1000 | K32: 1000 | L32: 1000 | M32: 1000 | N32: 1000 | O32: 1000 | P32: 1000 | Q32: =SUM(E32:P32) -> 12000
A33: Packing | B33: 200 | C33: 200 | D33: 200 | E33: 200 | F33: 200 | G33: 200 | H33: 200 | I33: 200 | J33: 200 | K33: 500 | L33: 500 | M33: 500 | N33: 500 | O33: 500 | P33: 500 | Q33: =SUM(E33:P33) -> 4200
A34: Outlet Ware (Disposables) | B34: 500 | C34: 500 | D34: 500 | E34: 500 | F34: 500 | G34: 500 | H34: 500 | I34: 500 | J34: 500 | K34: 500 | L34: 500 | M34: 500 | N34: 500 | O34: 500 | P34: 500 | Q34: =SUM(E34:P34) -> 6000
A35: Total Semi Variable Expenses | B35: =SUM(B28:B34) -> 5100 | C35: =SUM(C28:C34) -> 5100 | D35: =SUM(D28:D34) -> 5100 | E35: =SUM(E28:E34) -> 5100 | F35: =SUM(F28:F34) -> 9500 | G35: =SUM(G28:G34) -> 8600 | H35: =SUM(H28:H34) -> 5100 | I35: =SUM(I28:I34) -> 5100 | ... P35: =SUM(P28:P34) -> 5400 | Q35: =SUM(E35:P35) -> 70900
A36: % of Sales | B36: =B35/B10 -> 0.076304356 | C36: =C35/C10 -> 0.15666278 | D36: =D35/D10 -> 0.039189244 | E36: =E35/E12 -> 0.021609273 | F36: =F35/F12 -> 0.034425928 | G36: =G35/G12 -> #DIV/0! | H36: =H35/H12 -> 0.015165031 | I36: =I35/I12 -> 0.01399849 | J36: =J35/J12 -> 0.011373773 | K36: =K35/K12 -> 0.0096342551 | L36: =L35/L12 -> 0.0080285459 | ... Q36: =Q35/Q12 -> 0.012446043
A37: Administration Cost
A38: Repairs & Maintenance | B38: 0 | C38: 0 | D38: 0 | E38: 0 | F38: 0 | G38: 0 | H38: 0 | I38: 0 | J38: 0 | K38: 0 | L38: 0 | M38: 0 | N38: 0 | O38: 0 | P38: 0 | Q38: =SUM(G38:P38) -> 0
A39: BMC garbage collection | B39: 0 | C39: 0 | D39: 0 | E39: 0 | F39: 0 | G39: 0 | H39: 0 | I39: 0 | J39: 0 | K39: 0 | L39: 0 | M39: 0 | N39: 0 | O39: 0 | P39: 0 | Q39: =SUM(E39:P39) -> 0
A40: Local Conveyance | B40: 0 | C40: 0 | D40: 0 | E40: 0 | F40: 0 | G40: 0 | H40: 0 | I40: 0 | J40: 0 | K40: 0 | L40: 0 | M40: 0 | N40: 0 | O40: 0 | P40: 0 | Q40: =SUM(E40:P40) -> 0
A41: Transport for purchases goods only | B41: =4650 -> 4650 | C41: =5708+4400 -> 10108 | D41: 7000 | E41: 5000 | F41: 24801 | G41: 0 | H41: 0 | I41: 0 | J41: 0 | K41: 0 | L41: 0 | M41: 0 | N41: 0 | O41: 0 | P41: 0 | Q41: =SUM(E41:P41) -> 29801
...

Sheet Cashflow 
A1: 2025
A2: Revenue flow (Part A) | B2: Jan for Dec payments | C2: Feb for Jan Payments | D2: March for Feb Payments | E2: April for March Payments | F2: May for April Payments | G2: June for May Payments
B3: Acutal | C3: Actual | D3: Acutal | E3: Actual | F3: Actual | G3: Actual
A4: Amount in account from 1st | B4: 311542 | C4: =B14 -> 166088 | D4: =C8-C12 -> 196423.72 | E4: =D14 -> 210619.72 | F4: =E15 -> 139416 | G4: =F15 -> 248910
A5: Other monthly rev | B5: 0 | C5: ='[2]FEB 25'!$L$33 -> 5859.72 | D5: 38414 | E5: ='[2]April 25 '!$L$33 -> 250490.3 | F5: ='[2]May 25'!$M$24 -> 93491.8 | G5: ='[3]June 25'!$M$26 -> 12106.8
A6: Old payments from vendors | B6: 0 | C6: 0 | D6: 7134 | E6: ='[2]March 25'!$L$11 -> 11282.865 | F6: ='[2]April 25 '!$M$11+'[2]April 25 '!$M$10+'[2]April 25 '!$M$8 -> 77059.9 | G6: 0
A7: investments against capex | B7: 0 | C7: 264000 | D7: =150000+100000+41600 -> 291600 | E7: =50000+75000+150000+150000 -> 425000 | F7: =186000+150000+100000+100000+81500+50000+30000 -> 697500 | G7: 0
A8: Total in in flow ongoing | B8: =SUM(B4:B7) -> 311542 | C8: =SUM(C4:C7) -> 435947.72 | D8: =SUM(D4:D7) -> 533571.72 | E8: =SUM(E4:E7) -> 897392.89 | F8: =SUM(F4:F7) -> 1007467.7 | G8: =SUM(G4:G7) -> 261016.8
A9: Fixed cost | B9: =B30 -> 83518 | C9: =C30 -> 31716 | D9: =D30 -> 52908 | E9: =E30 -> 128077 | F9: =F30 -> 326798 | G9: =G30 -> 266966
A10: Payments to made to vendors | B10: =B50 -> 61936 | C10: =C50 -> 207808 | D10: =D50 -> 270044 | E10: =E50 -> 589266 | F10: =F50 -> 458593 | G10: =G50 -> 32766
A11: Total ops cost and vendor payments | B11: =SUM(B9:B10) -> 145454 | C11: =SUM(C9:C10) -> 239524 | D11: =SUM(D9:D10) -> 322952 | E11: =SUM(E9:E10) -> 717343 | F11: =F30+F50 -> 785391 | G11: =SUM(G9:G10) -> 299732
A12: Paid | B12: =B11 -> 145454 | C12: =C11 -> 239524 | D12: =D11 -> 322952 | E12: =E30+E50-E44 -> 717343 | F12: =F11 -> 785391 | G12: =G43+G20+G21+G29 -> 77324
A13: Pending payments to clear before end of month Marked in Red | E13: =E44 -> 0 | F13: =F11-F12 -> 0 | G13: =G11-G12 -> 222408
A14: Blalance in Hand | B14: =B4-B12 -> 166088 | C14: =C8-C12 -> 196423.72 | D14: =D8-D12 -> 210619.72 | E14: =E8-E12 -> 180049.89 | F14: =F8-F12 -> 222076.7 | G14: =G8-G12 -> 183692.8
A15: Actual in Bank | E15: =143728-4312 -> 139416 | F15: 248910 | G15: 184305
A16: Diffrence as per acutal in account agains balance in hand | E16: =E15-E14 -> -40633.885 | F16: =F15-F14 -> 26833.3
A17: Operations cost
A18: 1st to 10th
A19: Rent TDS | B19: 4950 | C19: 4950 | D19: 4950 | E19: 4950 | F19: 4950 | G19: 4950
A20: Salary Unit | B20: 45000 | C20: =(27000/30)*4 -> 3600 | D20: 24000 | E20: =27000+500-200 -> 27300 | F20: =27000-200 -> 26800 | G20: =(27000/30*26)-200 -> 23200
A21: Salary HO | B21: 0 | C21: 0 | D21: 0 | E21: =50000 -> 50000 | F21: =50000 -> 50000 | G21: =50000 -> 50000
A22: Water | B22: 0 | C22: 3500 | D22: 3500 | E22: 3500 | F22: 3500 | G22: 3500
A23: Eletricity bill | B23: 7601 | C23: =4729 -> 4729 | D23: 6444 | E23: 9709 | F23: 10971 | G23: 10971
A24: Old vendor URGENT | G24: =47495 -> 47495
A25: PPT | B25: 200 | C25: =320+520 -> 840 | D25: 320 | E25: 500 | F25: 150000 | G25: 100000
A26: Mobile bill | B26: 827 | C26: 827 | D26: 827 | E26: 850 | F26: 827 | G26: 850
A27: CA fees | B27: 22940 | C27: 5270 | D27: 6400 | E27: 27280 | F27: 73750 | G27: 24000
A28: Interest | B28: 0 | C28: 0 | D28: 0 | E28: 0 | F28: 0 | G28: 0
A29: Petty cash | B29: 2000 | C29: 8000 | D29: 6467 | E29: =2988+1000 -> 3988 | F29: 6000 | G29: 2000
A30: Total Operations cost | B30: =SUM(B19:B29) -> 83518 | C30: =SUM(C19:C29) -> 31716 | D30: =SUM(D19:D29) -> 52908 | E30: =SUM(E19:E29) -> 128077 | F30: =SUM(F19:F29) -> 326798 | G30: =SUM(G19:G29) -> 266966
A31: Vendor Payments against Capex
A32: 10th To 20 th
A33: Dishwasher Paid on | B33: 0 | C33: 50650 | D33: 70000 | E33: 100000 | F33: 0 | G33: 0
A34: Others (Coffee tea for office) | B34: 0 | C34: 0 | D34: 0 | E34: =1012 -> 1012 | F34: 0 | G34: 0
A35: CCG Amazon | E35: =14602+4312 -> 18914 | F35: =8678 -> 8678 | G35: 0
A36: Daily Staff on per day bases | B36: 0 | C36: 0 | D36: 0 | E36: 0 | F36: =1650+2750 -> 4400 | G36: 0
A37: Entertaiment for clients on store | E37: 4514 | F37: 0 | G37: 0
A38: Other Peronal CCG sold to store | E38: 20000 | F38: 0 | G38: 0
A39: New purchases of CCG | B39: 0 | C39: 0 | D39: 0 | E39: =11399+11269 -> 22668 | F39: =29741+1935+(2513*2) -> 36702 | G39: 0
A40: Clean Well services | B40: ='PnL Jan 25 to Mar 26'!B19 -> 57286 | C40: ='PnL Jan 25 to Mar 26'!C19 -> 56050 | D40: 49232 | E40: 49248 | F40: ='PnL Jan 25 to Mar 26'!E19 -> 39580 | G40: ='PnL Jan 25 to Mar 26'!F19 -> 30642
...

Sheet Rev Day wise break up 
A1: Month | C1: April | D1: May | E1: June | F1: July | G1: Aug | H1: Sep | I1: Oct | J1: Nov | K1: Dec | L1: Jan | M1: Feb | N1: March
A2: Budget Net Rev | C2: 200000 | D2: ='PnL Jan 25 to Mar 26'!F5 -> 220000 | E2: ='PnL Jan 25 to Mar 26'!G5 -> 250000 | F2: ='PnL Jan 25 to Mar 26'!H6 -> 300000 | G2: ='PnL Jan 25 to Mar 26'!I6 -> 325000 | H2: ='PnL Jan 25 to Mar 26'!J6 -> 400000 | I2: ='PnL Jan 25 to Mar 26'!K6 -> 500000 | J2: ='PnL Jan 25 to Mar 26'!L6 -> 600000 | K2: ='PnL Jan 25 to Mar 26'!M6 -> 700000 | L2: ='PnL Jan 25 to Mar 26'!N6 -> 650000 | M2: ='PnL Jan 25 to Mar 26'!O6 -> 600000 | N2: ='PnL Jan 25 to Mar 26'!P6 -> 550000
A3: Acutal Net Rev | C3: ='PnL Jan 25 to Mar 26'!E10 -> 212585 | D3: ='[2]May 25'!$J$24 -> 233860 | E3: ='[2]June 25'!$J$26 -> 68098
A4: Varaince | C4: 0
A5: Avg weekly | C5: =C3/4 -> 53146.25 | D5: =D3/4 -> 58465 | E5: =E3/4 -> 17024.5 | F5: =F3/4 -> 0 | G5: =G3/4 -> 0 | H5: =H3/4 -> 0 | I5: =I3/4 -> 0 | J5: =J3/4 -> 0 | ... N5: =N3/4 -> 0
A6: Rev % | B6: %
A7: Mon | B7: 0.1 | C7: =C3*B7 -> 21258.5 | D7: =D3*B7 -> 23386 | E7: =E5*B7 -> 1702.45 | F7: =F5*B7 -> 0 | G7: =G5*B7 -> 0 | H7: =H5*B7 -> 0 | I7: =I5*B7 -> 0 | J7: =J5*B7 -> 0 | K7: =K5*B7 -> 0 | L7: =L5*B7 -> 0 | M7: =M5*B7 -> 0 | N7: =N5*B7 -> 0
A8: Tue | B8: 0.1 | C8: =C3*B8 -> 21258.5 | D8: =D3*B8 -> 23386 | E8: =E5*B8 -> 1702.45 | F8: =F5*B8 -> 0 | G8: =G5*B8 -> 0 | H8: =H5*B8 -> 0 | I8: =I5*B8 -> 0 | J8: =J5*B8 -> 0 | K8: =K5*B8 -> 0 | L8: =L5*B8 -> 0 | M8: =M5*B8 -> 0 | N8: =N5*B8 -> 0
A9: Wed | B9: 0.15 | C9: =C3*B9 -> 31887.75 | D9: =D3*B9 -> 35079 | E9: =E5*B9 -> 2553.675 | F9: =F5*B9 -> 0 | G9: =G5*B9 -> 0 | H9: =H5*B9 -> 0 | I9: =I5*B9 -> 0 | J9: =J5*B9 -> 0 | K9: =K5*B9 -> 0 | L9: =L5*B9 -> 0 | M9: =M5*B9 -> 0 | N9: =N5*B9 -> 0
A10: Thrus | B10: 0.15 | C10: =C3*B10 -> 31887.75 | D10: =D3*B10 -> 35079 | E10: =E5*B10 -> 2553.675 | F10: =F5*B10 -> 0 | G10: =G5*B10 -> 0 | H10: =H5*B10 -> 0 | I10: =I5*B10 -> 0 | J10: =J5*B10 -> 0 | K10: =K5*B10 -> 0 | L10: =L5*B10 -> 0 | M10: =M5*B10 -> 0 | N10: =N5*B10 -> 0
A11: Fri | B11: 0.25 | C11: =C3*B11 -> 53146.25 | D11: =D3*B11 -> 58465 | E11: =E5*B11 -> 4256.125 | F11: =F5*B11 -> 0 | G11: =G5*B11 -> 0 | H11: =H5*B11 -> 0 | I11: =I5*B11 -> 0 | J11: =J5*B11 -> 0 | K11: =K5*B11 -> 0 | L11: =L5*B11 -> 0 | M11: =M5*B11 -> 0 | N11: =N5*B11 -> 0
A12: Sat | B12: 0.25 | C12: =C3*B12 -> 53146.25 | D12: =D3*B12 -> 58465 | E12: =E5*B12 -> 4256.125 | F12: =F5*B12 -> 0 | G12: =G5*B12 -> 0 | H12: =H5*B12 -> 0 | I12: =I5*B12 -> 0 | J12: =J5*B12 -> 0 | K12: =K5*B12 -> 0 | L12: =L5*B12 -> 0 | M12: =M5*B12 -> 0 | N12: =N5*B12 -> 0
A13: Sun
B14: =SUM(B7:B13) -> 1 | C14: =SUM(C7:C13) -> 212585 | D14: =SUM(D7:D13) -> 233860 | E14: =SUM(E7:E13) -> 17024.5 | F14: =SUM(F7:F13) -> 0 | G14: =SUM(G7:G13) -> 0 | H14: =SUM(H7:H13) -> 0 | I14: =SUM(I7:I13) -> 0 | ... N14: =SUM(N7:N13) -> 0
A15: AVG Per day | C15: =C3/30.5 -> 6970 | D15: =D3/30.5 -> 7667.541 | E15: =E3/30.5 -> 2232.7213

Sheet Sal and fix working cap cost 
A3: Heads | B3: Unit | C3: Name | D3: Salary per unit | E3: Total Staff needed | F3: Total salary CTC
A4: Office
A5: Managing Partner | B5: 1 | C5: Samir Chhabria | D5: 50000 | E5: 1 | F5: 50200
A6: Asst Unit Manager | B6: 1 | C6: Ashish Suve | D6: 27000 | E6: 1 | F6: 27000
A7: HK | B7: 0 | C7: 0 | D7: 0 | E7: 0 | F7: =D7*E7 -> 0
A8: WC & Car cleaning | B8: 1 | D8: 15000 | E8: 0 | F8: =D8 -> 15000
B9: =SUM(B6:B8) -> 2 | E9: =SUM(E5:E8) -> 2 | F9: =SUM(F5:F8) -> 92200
A10: Full Utility for DW , Loading ,Unlaoding , office and warehouse cleaing | B10: 1 | C10: Clean well | D10: 17500 | E10: 1 | F10: =D10*E10 -> 17500
A11: Total | B11: =SUM(B10:B10) -> 1 | E11: =SUM(E10:E10) -> 1 | F11: =SUM(F10:F10) -> 17500
A12: Total | E12: =E9+E11 -> 3 | F12: =F9+F11 -> 109700
A14: Total Salary | B14: =F12 -> 109700
A16: Heads | B16: Dec | C16: Jan | D16: Feb | E16: March | F16: April
A17: Rent | B17: =4700+250 -> 4950 | C17: =4700+250 -> 4950 | D17: =4700+250 -> 4950 | E17: =4700+250 -> 4950 | F17: =4700+250 -> 4950
A18: Sal | B18: =45000/30*15 -> 22500 | C18: =27000/30*5 -> 4500 | D18: 24000 | E18: 27000 | F18: =27000+50000 -> 77000
A19: Out sourced Sal | B19: 0 | C19: 57286 | D19: 56050 | E19: =(46660*18%)+46660 -> 55058.8 | F19: =(35000*18%)+35000 -> 41300
A20: Eletricty | B20: 7885 | C20: 3700 | D20: 6444 | E20: 7500 | F20: 7500
A21: Water | B21: 3500 | C21: 3500 | D21: 3500 | E21: 3500 | F21: 3500
A22: Staff drinking water | B22: 0 | C22: 0 | D22: 750 | E22: 750 | F22: 750
A23: Internet | B23: 16000 | C23: 16000 | D23: 16000 | E23: 16000 | F23: 16000
A24: Phone | B24: 900 | C24: 900 | D24: 900 | E24: 900 | F24: 900
A25: Total | B25: =SUM(B17:B24) -> 55735 | C25: =SUM(C17:C24) -> 90836 | D25: =SUM(D17:D24) -> 112594 | E25: =SUM(E17:E24) -> 115658.8 | F25: =SUM(F17:F24) -> 151900
